<?xml version="1.0"?>
<robot name="simple_humanoid">
  <link name="base_link"/>

  <link name="torso">
    <visual>
      <geometry>
        <box size="0.2 0.3 0.5"/>
      </geometry>
    </visual>
    <collision>
      <geometry>
        <box size="0.2 0.3 0.5"/>
      </geometry>
    </collision>
    <inertial>
      <mass value="10"/>
      <inertia ixx="0.4" ixy="0.0" ixz="0.0" iyy="0.4" iyz="0.0" izz="0.2"/>
    </inertial>
  </link>

  <joint name="base_to_torso" type="fixed">
    <parent link="base_link"/>
    <child link="torso"/>
    <origin xyz="0 0 0.5"/>
  </joint>

  <link name="left_leg">
    <visual>
      <geometry>
        <box size="0.1 0.1 0.4"/>
      </geometry>
    </visual>
    <collision>
      <geometry>
        <box size="0.1 0.1 0.4"/>
      </geometry>
    </collision>
    <inertial>
      <mass value="3"/>
      <inertia ixx="0.05" ixy="0.0" ixz="0.0" iyy="0.05" iyz="0.0" izz="0.01"/>
    </inertial>
  </link>

  <joint name="torso_to_left_leg" type="continuous">
    <parent link="torso"/>
    <child link="left_leg"/>
    <origin xyz="-0.1 0 -0.3"/>
    <axis xyz="1 0 0"/>
  </joint>

</robot>
