<?xml version="1.0"?>
<robot name="simple_humanoid">
  <link name="base_link"/>

  <link name="torso">
    <visual>
      <geometry>
        <box size="0.2 0.3 0.5"/>
      </geometry>
    </visual>
    <collision>
      <geometry>
        <box size="0.2 0.3 0.5"/>
      </geometry>
    </collision>
    <inertial>
      <mass value="10"/>
      <inertia ixx="0.4" ixy="0.0" ixz="0.0" iyy="0.4" iyz="0.0" izz="0.2"/>
    </inertial>
  </link>

  <joint name="base_to_torso" type="fixed">
    <parent link="base_link"/>
    <child link="torso"/>
    <origin xyz="0 0 0.5"/>
  </joint>

  <link name="left_leg">
    <visual>
      <geometry>
        <box size="0.1 0.1 0.4"/>
      </geometry>
    </visual>
    <collision>
      <geometry>
        <box size="0.1 0.1 0.4"/>
      </geometry>
    </collision>
    <inertial>
      <mass value="3"/>
      <inertia ixx="0.05" ixy="0.0" ixz="0.0" iyy="0.05" iyz="0.0" izz="0.01"/>
    </inertial>
  </link>

  <joint name="torso_to_left_leg" type="continuous">
    <parent link="torso"/>
    <child link="left_leg"/>
    <origin xyz="-0.1 0 -0.3"/>
    <axis xyz="1 0 0"/>
  </joint>

  <gazebo reference="torso">
    <sensor type="ray" name="lidar">
      <pose>0 0 0.3 0 0 0</pose>
      <visualize>true</visualize>
      <update_rate>10</update_rate>
      <ray>
        <scan>
          <horizontal>
            <samples>720</samples>
            <resolution>1</resolution>
            <min_angle>-1.570796</min_angle>
            <max_angle>1.570796</max_angle>
          </horizontal>
        </scan>
        <range>
          <min>0.10</min>
          <max>30.0</max>
          <resolution>0.01</resolution>
        </range>
      </ray>
      <plugin name="gazebo_ros_head_hokuyo_controller" filename="libgazebo_ros_laser.so">
        <topicName>/lidar/points</topicName>
        <frameName>torso</frameName>
      </plugin>
    </sensor>
  </gazebo>

  <gazebo reference="base_link">
    <sensor type="depth" name="depth_camera">
      <update_rate>30.0</update_rate>
      <camera name="head">
        <horizontal_fov>1.3962634</horizontal_fov>
        <image>
          <width>800</width>
          <height>800</height>
          <format>R8G8B8</format>
        </image>
        <clip>
          <near>0.02</near>
          <far>300</far>
        </clip>
      </camera>
      <plugin name="depth_camera_controller" filename="libgazebo_ros_depth_camera.so">
        <baseline>0.2</baseline>
        <alwaysOn>true</alwaysOn>
        <updateRate>0.0</updateRate>
        <cameraName>camera</cameraName>
        <imageTopicName>/depth_camera/image_raw</imageTopicName>
        <cameraInfoTopicName>/depth_camera/camera_info</cameraInfoTopicName>
        <frameName>base_link</frameName>
        <hackBaseline>0.07</hackBaseline>
        <pointCloudCutoff>0.5</pointCloudCutoff>
      </plugin>
    </sensor>
  </gazebo>

</robot>
